Workbook

Sheet Инструкция
A1: ZAPKIT — таблица закупки и цен
A3: Как пользоваться:
A4: 1. «Поставщики» — заполните условия каждого поставщика: склад в Сочи/Адлере, отсечка, срок, возврат.
A5: 2. «Состав» — для каждой позиции подберите по VIN/каталогу бренд и артикул и впишите цены у тех поставщиков, где она есть.
A6: Лучшая цена, поставщик и сумма посчитаются сами. Кол-во 0 = позиция не входит (например, помпа); поставьте 1, если нужна.
A7: 3. «Киты» — сами посчитаются закупка, цена на Авито и прибыль до налога в двух вариантах: оплата через Авито Доставку и прямым переводом.
A8: Впишите минимальную цену конкурентов — появится сравнение с рынком. Колонка Y «Цена по рынку (база)» — если цену кита ставим по рынку, а не по наценке.
A9: 4. «Параметры» — наценка, повышение цен (+5%), комиссии, резерв на товар, постоянные расходы и план заказов. Поменяете там — пересчитается всё.
A10: 5. «Прогноз» — выручка и прибыль за месяц: ТО, ГРМ и тормоз-киты отдельно и вместе, точка безубыточности.
A11: 6. «Моторы» — справка: где цепь, где ремень, что входит в ГРМ-кит, источники.
A12: 7. «Заявки» — каждое обращение на Авито: VIN, статус, следующий шаг. Справа считается воронка. Как вести — docs/avito/client-loop.md.
A14: Обозначения:
... A17: Серая строка «ПРИМЕР» на листах — образец заполнения, её можно удалить.

Sheet Киты
A1: Кит | B1: Вид | C1: Машина | D1: Мотор | E1: Привод ГРМ | F1: Приоритет | G1: Заголовок для Авито | H1: Главное фото (avito/png/…) | I1: Детали, ₽ | J1: Позиций без цены | K1: Упаковка, ₽ | L1: Закупка, ₽ | M1: Цена на Авито, ₽ | N1: Мин. цена конкурентов, ₽ | O1: Сравнение с рынком | P1: Комиссия Авито, ₽ | Q1: Комиссия банка, ₽ | R1: Показы, ₽ | S1: Резерв на товар, ₽ | T1: Постоянные расходы, ₽ | U1: Прибыль: Авито Доставка, ₽ | V1: Прибыль: перевод, ₽ | W1: Маржа (Авито Доставка) | X1: Статус | Y1: Цена по рынку (база), ₽
A2: TO-01 | B2: ТО | C2: Hyundai Solaris 2010–2017 | D2: G4FA / G4FC | E2: цепь | F2: высокий | G2: ТО-кит Hyundai Solaris 2010–2017: масло и фильтры | H2: to-01-solaris-2010-1-main.png | I2: =IF(SUMIFS(Состав!$R:$R,Состав!$A:$A,A2)=0,"",SUMIFS(Состав!$R:$R,Состав!$A:$A,A2)) | J2: =COUNTIFS(Состав!$A:$A,A2,Состав!$P:$P,"",Состав!$D:$D,">0") -> 5 | K2: =IF(I2="","",Параметры!$B$3) | L2: =IF(I2="","",I2+K2) | M2: =IF(I2="","",CEILING((IF(Y2<>"",Y2,CEILING((I2*(1+Параметры!$B$9*Параметры!$B$10)+K2)*(1+Параметры!$B$2),Параметры!$B$4)-Параметры!$B$5))*(1+Параметры!$B$6),Параметры!$B$4)-Параметры!$B$5) | O2: =IF(OR(M2="",N2=""),"",IF(M2<=N2,"не дороже рынка","дороже рынка")) | P2: =IF(M2="","",M2*Параметры!$B$7) | Q2: =IF(M2="","",M2*Параметры!$B$11) | R2: =IF(M2="","",Параметры!$B$8) | S2: =IF(I2="","",I2*Параметры!$B$9) | T2: =IF(M2="","",Параметры!$B$19) | U2: =IF(M2="","",M2-L2-P2-R2-S2-T2) | V2: =IF(M2="","",M2-L2-Q2-R2-S2-T2-Параметры!$B$12) | W2: =IF(U2="","",U2/M2) | X2: не выложен
A3: TO-02 | B3: ТО | C3: Hyundai Solaris 2017–2022 | D3: G4LC / G4FG | E3: цепь | F3: высокий | G3: ТО-кит Hyundai Solaris 2017–2022: масло и фильтры | H3: to-02-solaris-2017-1-main.png | I3: =IF(SUMIFS(Состав!$R:$R,Состав!$A:$A,A3)=0,"",SUMIFS(Состав!$R:$R,Состав!$A:$A,A3)) | J3: =COUNTIFS(Состав!$A:$A,A3,Состав!$P:$P,"",Состав!$D:$D,">0") -> 5 | K3: =IF(I3="","",Параметры!$B$3) | L3: =IF(I3="","",I3+K3) | M3: =IF(I3="","",CEILING((IF(Y3<>"",Y3,CEILING((I3*(1+Параметры!$B$9*Параметры!$B$10)+K3)*(1+Параметры!$B$2),Параметры!$B$4)-Параметры!$B$5))*(1+Параметры!$B$6),Параметры!$B$4)-Параметры!$B$5) | O3: =IF(OR(M3="",N3=""),"",IF(M3<=N3,"не дороже рынка","дороже рынка")) | P3: =IF(M3="","",M3*Параметры!$B$7) | Q3: =IF(M3="","",M3*Параметры!$B$11) | R3: =IF(M3="","",Параметры!$B$8) | S3: =IF(I3="","",I3*Параметры!$B$9) | T3: =IF(M3="","",Параметры!$B$19) | U3: =IF(M3="","",M3-L3-P3-R3-S3-T3) | V3: =IF(M3="","",M3-L3-Q3-R3-S3-T3-Параметры!$B$12) | W3: =IF(U3="","",U3/M3) | X3: не выложен
A4: TO-03 | B4: ТО | C4: Kia Rio 2011–2017 | D4: G4FA / G4FC | E4: цепь | F4: высокий | G4: ТО-кит Kia Rio 3 2011–2017: масло и фильтры | H4: to-03-rio-3-1-main.png | I4: =IF(SUMIFS(Состав!$R:$R,Состав!$A:$A,A4)=0,"",SUMIFS(Состав!$R:$R,Состав!$A:$A,A4)) | J4: =COUNTIFS(Состав!$A:$A,A4,Состав!$P:$P,"",Состав!$D:$D,">0") -> 5 | K4: =IF(I4="","",Параметры!$B$3) | L4: =IF(I4="","",I4+K4) | M4: =IF(I4="","",CEILING((IF(Y4<>"",Y4,CEILING((I4*(1+Параметры!$B$9*Параметры!$B$10)+K4)*(1+Параметры!$B$2),Параметры!$B$4)-Параметры!$B$5))*(1+Параметры!$B$6),Параметры!$B$4)-Параметры!$B$5) | O4: =IF(OR(M4="",N4=""),"",IF(M4<=N4,"не дороже рынка","дороже рынка")) | P4: =IF(M4="","",M4*Параметры!$B$7) | Q4: =IF(M4="","",M4*Параметры!$B$11) | R4: =IF(M4="","",Параметры!$B$8) | S4: =IF(I4="","",I4*Параметры!$B$9) | T4: =IF(M4="","",Параметры!$B$19) | U4: =IF(M4="","",M4-L4-P4-R4-S4-T4) | V4: =IF(M4="","",M4-L4-Q4-R4-S4-T4-Параметры!$B$12) | W4: =IF(U4="","",U4/M4) | X4: не выложен
A5: TO-04 | B5: ТО | C5: Kia Rio 2017–2021 | D5: G4LC / G4FG | E5: цепь | F5: высокий | G5: ТО-кит Kia Rio 4 2017–2021: масло и фильтры | H5: to-04-rio-4-1-main.png | I5: =IF(SUMIFS(Состав!$R:$R,Состав!$A:$A,A5)=0,"",SUMIFS(Состав!$R:$R,Состав!$A:$A,A5)) | J5: =COUNTIFS(Состав!$A:$A,A5,Состав!$P:$P,"",Состав!$D:$D,">0") -> 5 | K5: =IF(I5="","",Параметры!$B$3) | L5: =IF(I5="","",I5+K5) | M5: =IF(I5="","",CEILING((IF(Y5<>"",Y5,CEILING((I5*(1+Параметры!$B$9*Параметры!$B$10)+K5)*(1+Параметры!$B$2),Параметры!$B$4)-Параметры!$B$5))*(1+Параметры!$B$6),Параметры!$B$4)-Параметры!$B$5) | O5: =IF(OR(M5="",N5=""),"",IF(M5<=N5,"не дороже рынка","дороже рынка")) | P5: =IF(M5="","",M5*Параметры!$B$7) | Q5: =IF(M5="","",M5*Параметры!$B$11) | R5: =IF(M5="","",Параметры!$B$8) | S5: =IF(I5="","",I5*Параметры!$B$9) | T5: =IF(M5="","",Параметры!$B$19) | U5: =IF(M5="","",M5-L5-P5-R5-S5-T5) | V5: =IF(M5="","",M5-L5-Q5-R5-S5-T5-Параметры!$B$12) | W5: =IF(U5="","",U5/M5) | X5: не выложен
A6: TO-05 | B6: ТО | C6: VW Polo 1.6 CFNA | D6: CFNA / CFNB | E6: цепь | F6: высокий | G6: ТО-кит VW Polo 1.6 CFNA: масло и фильтры | H6: to-05-polo-cfna-1-main.png | I6: =IF(SUMIFS(Состав!$R:$R,Состав!$A:$A,A6)=0,"",SUMIFS(Состав!$R:$R,Состав!$A:$A,A6)) | J6: =COUNTIFS(Состав!$A:$A,A6,Состав!$P:$P,"",Состав!$D:$D,">0") -> 5 | K6: =IF(I6="","",Параметры!$B$3) | L6: =IF(I6="","",I6+K6) | M6: =IF(I6="","",CEILING((IF(Y6<>"",Y6,CEILING((I6*(1+Параметры!$B$9*Параметры!$B$10)+K6)*(1+Параметры!$B$2),Параметры!$B$4)-Параметры!$B$5))*(1+Параметры!$B$6),Параметры!$B$4)-Параметры!$B$5) | O6: =IF(OR(M6="",N6=""),"",IF(M6<=N6,"не дороже рынка","дороже рынка")) | P6: =IF(M6="","",M6*Параметры!$B$7) | Q6: =IF(M6="","",M6*Параметры!$B$11) | R6: =IF(M6="","",Параметры!$B$8) | S6: =IF(I6="","",I6*Параметры!$B$9) | T6: =IF(M6="","",Параметры!$B$19) | U6: =IF(M6="","",M6-L6-P6-R6-S6-T6) | V6: =IF(M6="","",M6-L6-Q6-R6-S6-T6-Параметры!$B$12) | W6: =IF(U6="","",U6/M6) | X6: не выложен
A7: TO-06 | B7: ТО | C7: VW Polo 1.6 CWVA | D7: CWVA / CWVB | E7: ремень | F7: высокий | G7: ТО-кит VW Polo 1.6 CWVA: масло и фильтры | H7: to-06-polo-cwva-1-main.png | I7: =IF(SUMIFS(Состав!$R:$R,Состав!$A:$A,A7)=0,"",SUMIFS(Состав!$R:$R,Состав!$A:$A,A7)) | J7: =COUNTIFS(Состав!$A:$A,A7,Состав!$P:$P,"",Состав!$D:$D,">0") -> 5 | K7: =IF(I7="","",Параметры!$B$3) | L7: =IF(I7="","",I7+K7) | M7: =IF(I7="","",CEILING((IF(Y7<>"",Y7,CEILING((I7*(1+Параметры!$B$9*Параметры!$B$10)+K7)*(1+Параметры!$B$2),Параметры!$B$4)-Параметры!$B$5))*(1+Параметры!$B$6),Параметры!$B$4)-Параметры!$B$5) | O7: =IF(OR(M7="",N7=""),"",IF(M7<=N7,"не дороже рынка","дороже рынка")) | P7: =IF(M7="","",M7*Параметры!$B$7) | Q7: =IF(M7="","",M7*Параметры!$B$11) | R7: =IF(M7="","",Параметры!$B$8) | S7: =IF(I7="","",I7*Параметры!$B$9) | T7: =IF(M7="","",Параметры!$B$19) | U7: =IF(M7="","",M7-L7-P7-R7-S7-T7) | V7: =IF(M7="","",M7-L7-Q7-R7-S7-T7-Параметры!$B$12) | W7: =IF(U7="","",U7/M7) | X7: не выложен
A8: TO-07 | B8: ТО | C8: Haval Jolion 1.5T | D8: GW4B15A | E8: цепь | F8: высокий | G8: ТО-кит Haval Jolion 1.5T: масло и фильтры | H8: to-07-jolion-1-main.png | I8: =IF(SUMIFS(Состав!$R:$R,Состав!$A:$A,A8)=0,"",SUMIFS(Состав!$R:$R,Состав!$A:$A,A8)) | J8: =COUNTIFS(Состав!$A:$A,A8,Состав!$P:$P,"",Состав!$D:$D,">0") -> 5 | K8: =IF(I8="","",Параметры!$B$3) | L8: =IF(I8="","",I8+K8) | M8: =IF(I8="","",CEILING((IF(Y8<>"",Y8,CEILING((I8*(1+Параметры!$B$9*Параметры!$B$10)+K8)*(1+Параметры!$B$2),Параметры!$B$4)-Параметры!$B$5))*(1+Параметры!$B$6),Параметры!$B$4)-Параметры!$B$5) | O8: =IF(OR(M8="",N8=""),"",IF(M8<=N8,"не дороже рынка","дороже рынка")) | P8: =IF(M8="","",M8*Параметры!$B$7) | Q8: =IF(M8="","",M8*Параметры!$B$11) | R8: =IF(M8="","",Параметры!$B$8) | S8: =IF(I8="","",I8*Параметры!$B$9) | T8: =IF(M8="","",Параметры!$B$19) | U8: =IF(M8="","",M8-L8-P8-R8-S8-T8) | V8: =IF(M8="","",M8-L8-Q8-R8-S8-T8-Параметры!$B$12) | W8: =IF(U8="","",U8/M8) | X8: не выложен
A9: TO-08 | B9: ТО | C9: Haval F7 / F7x 1.5T | D9: GW4B15 | E9: цепь | F9: высокий | G9: ТО-кит Haval F7/F7x 1.5T: масло и фильтры | H9: to-08-f7-15-1-main.png | I9: =IF(SUMIFS(Состав!$R:$R,Состав!$A:$A,A9)=0,"",SUMIFS(Состав!$R:$R,Состав!$A:$A,A9)) | J9: =COUNTIFS(Состав!$A:$A,A9,Состав!$P:$P,"",Состав!$D:$D,">0") -> 5 | K9: =IF(I9="","",Параметры!$B$3) | L9: =IF(I9="","",I9+K9) | M9: =IF(I9="","",CEILING((IF(Y9<>"",Y9,CEILING((I9*(1+Параметры!$B$9*Параметры!$B$10)+K9)*(1+Параметры!$B$2),Параметры!$B$4)-Параметры!$B$5))*(1+Параметры!$B$6),Параметры!$B$4)-Параметры!$B$5) | O9: =IF(OR(M9="",N9=""),"",IF(M9<=N9,"не дороже рынка","дороже рынка")) | P9: =IF(M9="","",M9*Параметры!$B$7) | Q9: =IF(M9="","",M9*Параметры!$B$11) | R9: =IF(M9="","",Параметры!$B$8) | S9: =IF(I9="","",I9*Параметры!$B$9) | T9: =IF(M9="","",Параметры!$B$19) | U9: =IF(M9="","",M9-L9-P9-R9-S9-T9) | V9: =IF(M9="","",M9-L9-Q9-R9-S9-T9-Параметры!$B$12) | W9: =IF(U9="","",U9/M9) | X9: не выложен
A10: TO-09 | B10: ТО | C10: Haval F7 / F7x 2.0T | D10: GW4C20 | E10: цепь | F10: высокий | G10: ТО-кит Haval F7/F7x 2.0T: масло и фильтры | H10: to-09-f7-20-1-main.png | I10: =IF(SUMIFS(Состав!$R:$R,Состав!$A:$A,A10)=0,"",SUMIFS(Состав!$R:$R,Состав!$A:$A,A10)) | J10: =COUNTIFS(Состав!$A:$A,A10,Состав!$P:$P,"",Состав!$D:$D,">0") -> 5 | K10: =IF(I10="","",Параметры!$B$3) | L10: =IF(I10="","",I10+K10) | M10: =IF(I10="","",CEILING((IF(Y10<>"",Y10,CEILING((I10*(1+Параметры!$B$9*Параметры!$B$10)+K10)*(1+Параметры!$B$2),Параметры!$B$4)-Параметры!$B$5))*(1+Параметры!$B$6),Параметры!$B$4)-Параметры!$B$5) | O10: =IF(OR(M10="",N10=""),"",IF(M10<=N10,"не дороже рынка","дороже рынка")) | P10: =IF(M10="","",M10*Параметры!$B$7) | Q10: =IF(M10="","",M10*Параметры!$B$11) | R10: =IF(M10="","",Параметры!$B$8) | S10: =IF(I10="","",I10*Параметры!$B$9) | T10: =IF(M10="","",Параметры!$B$19) | U10: =IF(M10="","",M10-L10-P10-R10-S10-T10) | V10: =IF(M10="","",M10-L10-Q10-R10-S10-T10-Параметры!$B$12) | W10: =IF(U10="","",U10/M10) | X10: не выложен
A11: TO-10 | B11: ТО | C11: Chery Tiggo 7 Pro 1.5T | D11: SQRE4T15C | E11: цепь | F11: высокий | G11: ТО-кит Chery Tiggo 7 Pro 1.5T: масло и фильтры | H11: to-10-tiggo-7pro-1-main.png | I11: =IF(SUMIFS(Состав!$R:$R,Состав!$A:$A,A11)=0,"",SUMIFS(Состав!$R:$R,Состав!$A:$A,A11)) | J11: =COUNTIFS(Состав!$A:$A,A11,Состав!$P:$P,"",Состав!$D:$D,">0") -> 5 | K11: =IF(I11="","",Параметры!$B$3) | L11: =IF(I11="","",I11+K11) | M11: =IF(I11="","",CEILING((IF(Y11<>"",Y11,CEILING((I11*(1+Параметры!$B$9*Параметры!$B$10)+K11)*(1+Параметры!$B$2),Параметры!$B$4)-Параметры!$B$5))*(1+Параметры!$B$6),Параметры!$B$4)-Параметры!$B$5) | O11: =IF(OR(M11="",N11=""),"",IF(M11<=N11,"не дороже рынка","дороже рынка")) | P11: =IF(M11="","",M11*Параметры!$B$7) | Q11: =IF(M11="","",M11*Параметры!$B$11) | R11: =IF(M11="","",Параметры!$B$8) | S11: =IF(I11="","",I11*Параметры!$B$9) | T11: =IF(M11="","",Параметры!$B$19) | U11: =IF(M11="","",M11-L11-P11-R11-S11-T11) | V11: =IF(M11="","",M11-L11-Q11-R11-S11-T11-Параметры!$B$12) | W11: =IF(U11="","",U11/M11) | X11: не выложен
A12: TO-11 | B12: ТО | C12: Chery Tiggo 4 Pro 1.5T | D12: SQRE4T15C | E12: цепь | F12: высокий | G12: ТО-кит Chery Tiggo 4 Pro 1.5T: масло и фильтры | H12: to-11-tiggo-4pro-1-main.png | I12: =IF(SUMIFS(Состав!$R:$R,Состав!$A:$A,A12)=0,"",SUMIFS(Состав!$R:$R,Состав!$A:$A,A12)) | J12: =COUNTIFS(Состав!$A:$A,A12,Состав!$P:$P,"",Состав!$D:$D,">0") -> 5 | K12: =IF(I12="","",Параметры!$B$3) | L12: =IF(I12="","",I12+K12) | M12: =IF(I12="","",CEILING((IF(Y12<>"",Y12,CEILING((I12*(1+Параметры!$B$9*Параметры!$B$10)+K12)*(1+Параметры!$B$2),Параметры!$B$4)-Параметры!$B$5))*(1+Параметры!$B$6),Параметры!$B$4)-Параметры!$B$5) | O12: =IF(OR(M12="",N12=""),"",IF(M12<=N12,"не дороже рынка","дороже рынка")) | P12: =IF(M12="","",M12*Параметры!$B$7) | Q12: =IF(M12="","",M12*Параметры!$B$11) | R12: =IF(M12="","",Параметры!$B$8) | S12: =IF(I12="","",I12*Параметры!$B$9) | T12: =IF(M12="","",Параметры!$B$19) | U12: =IF(M12="","",M12-L12-P12-R12-S12-T12) | V12: =IF(M12="","",M12-L12-Q12-R12-S12-T12-Параметры!$B$12) | W12: =IF(U12="","",U12/M12) | X12: не выложен
A13: TO-12 | B13: ТО | C13: Geely Coolray 1.5T | D13: JLH-3G15TD | E13: ремень + ремень помпы | F13: высокий | G13: ТО-кит Geely Coolray 1.5T: масло и фильтры | H13: to-12-coolray-1-main.png | I13: =IF(SUMIFS(Состав!$R:$R,Состав!$A:$A,A13)=0,"",SUMIFS(Состав!$R:$R,Состав!$A:$A,A13)) | J13: =COUNTIFS(Состав!$A:$A,A13,Состав!$P:$P,"",Состав!$D:$D,">0") -> 5 | K13: =IF(I13="","",Параметры!$B$3) | L13: =IF(I13="","",I13+K13) | M13: =IF(I13="","",CEILING((IF(Y13<>"",Y13,CEILING((I13*(1+Параметры!$B$9*Параметры!$B$10)+K13)*(1+Параметры!$B$2),Параметры!$B$4)-Параметры!$B$5))*(1+Параметры!$B$6),Параметры!$B$4)-Параметры!$B$5) | O13: =IF(OR(M13="",N13=""),"",IF(M13<=N13,"не дороже рынка","дороже рынка")) | P13: =IF(M13="","",M13*Параметры!$B$7) | Q13: =IF(M13="","",M13*Параметры!$B$11) | R13: =IF(M13="","",Параметры!$B$8) | S13: =IF(I13="","",I13*Параметры!$B$9) | T13: =IF(M13="","",Параметры!$B$19) | U13: =IF(M13="","",M13-L13-P13-R13-S13-T13) | V13: =IF(M13="","",M13-L13-Q13-R13-S13-T13-Параметры!$B$12) | W13: =IF(U13="","",U13/M13) | X13: не выложен
... A25: GRM-10 | B25: ГРМ | C25: Chery Tiggo 7 Pro / 4 Pro 1.5T | D25: SQRE4T15C | E25: цепь | F25: позже | G25: ГРМ-кит Chery Tiggo 7 Pro/4 Pro 1.5T: цепь | H25: grm-10-tiggo-7pro-1-main.png | I25: =IF(SUMIFS(Состав!$R:$R,Состав!$A:$A,A25)=0,"",SUMIFS(Состав!$R:$R,Состав!$A:$A,A25)) | J25: =COUNTIFS(Состав!$A:$A,A25,Состав!$P:$P,"",Состав!$D:$D,">0") -> 3 | K25: =IF(I25="","",Параметры!$B$3) | L25: =IF(I25="","",I25+K25) | M25: =IF(I25="","",CEILING((IF(Y25<>"",Y25,CEILING((I25*(1+Параметры!$B$9*Параметры!$B$10)+K25)*(1+Параметры!$B$2),Параметры!$B$4)-Параметры!$B$5))*(1+Параметры!$B$6),Параметры!$B$4)-Параметры!$B$5) | O25: =IF(OR(M25="",N25=""),"",IF(M25<=N25,"не дороже рынка","дороже рынка")) | P25: =IF(M25="","",M25*Параметры!$B$7) | Q25: =IF(M25="","",M25*Параметры!$B$11) | R25: =IF(M25="","",Параметры!$B$8) | S25: =IF(I25="","",I25*Параметры!$B$9) | T25: =IF(M25="","",Параметры!$B$19) | U25: =IF(M25="","",M25-L25-P25-R25-S25-T25) | V25: =IF(M25="","",M25-L25-Q25-R25-S25-T25-Параметры!$B$12) | W25: =IF(U25="","",U25/M25) | X25: не выложен
A26: GRM-12 | B26: ГРМ | C26: Geely Coolray 1.5T | D26: JLH-3G15TD | E26: ремень + ремень помпы | F26: высокий | G26: ГРМ-кит Gates Geely Coolray 1.5T: ремни и ролики | H26: grm-12-coolray-1-main.png | I26: =IF(SUMIFS(Состав!$R:$R,Состав!$A:$A,A26)=0,"",SUMIFS(Состав!$R:$R,Состав!$A:$A,A26)) | J26: =COUNTIFS(Состав!$A:$A,A26,Состав!$P:$P,"",Состав!$D:$D,">0") -> 2 | K26: =IF(I26="","",Параметры!$B$3) | L26: =IF(I26="","",I26+K26) | M26: =IF(I26="","",CEILING((IF(Y26<>"",Y26,CEILING((I26*(1+Параметры!$B$9*Параметры!$B$10)+K26)*(1+Параметры!$B$2),Параметры!$B$4)-Параметры!$B$5))*(1+Параметры!$B$6),Параметры!$B$4)-Параметры!$B$5) | O26: =IF(OR(M26="",N26=""),"",IF(M26<=N26,"не дороже рынка","дороже рынка")) | P26: =IF(M26="","",M26*Параметры!$B$7) | Q26: =IF(M26="","",M26*Параметры!$B$11) | R26: =IF(M26="","",Параметры!$B$8) | S26: =IF(I26="","",I26*Параметры!$B$9) | T26: =IF(M26="","",Параметры!$B$19) | U26: =IF(M26="","",M26-L26-P26-R26-S26-T26) | V26: =IF(M26="","",M26-L26-Q26-R26-S26-T26-Параметры!$B$12) | W26: =IF(U26="","",U26/M26) | X26: не выложен | Y26: 9990
A27: TRM-01 | B27: Тормоза | C27: Kia Rio 2017–2021 | D27: все моторы | E27: — | F27: высокий | G27: Тормоз-кит Kia Rio 4 2017–2021: диски и колодки | H27: trm-01-rio-4-1-main.png | I27: =IF(SUMIFS(Состав!$R:$R,Состав!$A:$A,A27)=0,"",SUMIFS(Состав!$R:$R,Состав!$A:$A,A27)) | J27: =COUNTIFS(Состав!$A:$A,A27,Состав!$P:$P,"",Состав!$D:$D,">0") -> 3 | K27: =IF(I27="","",Параметры!$B$3) | L27: =IF(I27="","",I27+K27) | M27: =IF(I27="","",CEILING((IF(Y27<>"",Y27,CEILING((I27*(1+Параметры!$B$9*Параметры!$B$10)+K27)*(1+Параметры!$B$2),Параметры!$B$4)-Параметры!$B$5))*(1+Параметры!$B$6),Параметры!$B$4)-Параметры!$B$5) | O27: =IF(OR(M27="",N27=""),"",IF(M27<=N27,"не дороже рынка","дороже рынка")) | P27: =IF(M27="","",M27*Параметры!$B$7) | Q27: =IF(M27="","",M27*Параметры!$B$11) | R27: =IF(M27="","",Параметры!$B$8) | S27: =IF(I27="","",I27*Параметры!$B$9) | T27: =IF(M27="","",Параметры!$B$19) | U27: =IF(M27="","",M27-L27-P27-R27-S27-T27) | V27: =IF(M27="","",M27-L27-Q27-R27-S27-T27-Параметры!$B$12) | W27: =IF(U27="","",U27/M27) | X27: не выложен | Y27: 4990
A28: TRM-02 | B28: Тормоза | C28: Hyundai Solaris 2017–2022 | D28: все моторы | E28: — | F28: высокий | G28: Тормоз-кит Hyundai Solaris 2017+: диски, колодки | H28: trm-02-solaris-2017-1-main.png | I28: =IF(SUMIFS(Состав!$R:$R,Состав!$A:$A,A28)=0,"",SUMIFS(Состав!$R:$R,Состав!$A:$A,A28)) | J28: =COUNTIFS(Состав!$A:$A,A28,Состав!$P:$P,"",Состав!$D:$D,">0") -> 3 | K28: =IF(I28="","",Параметры!$B$3) | L28: =IF(I28="","",I28+K28) | M28: =IF(I28="","",CEILING((IF(Y28<>"",Y28,CEILING((I28*(1+Параметры!$B$9*Параметры!$B$10)+K28)*(1+Параметры!$B$2),Параметры!$B$4)-Параметры!$B$5))*(1+Параметры!$B$6),Параметры!$B$4)-Параметры!$B$5) | O28: =IF(OR(M28="",N28=""),"",IF(M28<=N28,"не дороже рынка","дороже рынка")) | P28: =IF(M28="","",M28*Параметры!$B$7) | Q28: =IF(M28="","",M28*Параметры!$B$11) | R28: =IF(M28="","",Параметры!$B$8) | S28: =IF(I28="","",I28*Параметры!$B$9) | T28: =IF(M28="","",Параметры!$B$19) | U28: =IF(M28="","",M28-L28-P28-R28-S28-T28) | V28: =IF(M28="","",M28-L28-Q28-R28-S28-T28-Параметры!$B$12) | W28: =IF(U28="","",U28/M28) | X28: не выложен | Y28: 4990

Sheet Заявки
A1: № | B1: Дата и время | C1: Покупатель (имя на Авито) | D1: Откуда | E1: Кит / что спросил | F1: Машина | G1: VIN | H1: Статус | I1: Первый ответ, мин | J1: Сумма, ₽ | K1: Оплата | L1: Причина отказа | M1: Следующий шаг | N1: Когда | O1: Комментарий | Q1: Воронка (по всем строкам)
A2: ПРИМЕР | B2: 28.09 10:15 | C2: Андрей | D2: чат | E2: TRM-01 | F2: Kia Rio 2019 | G2: Z94C… | H2: 7. В обработке | I2: 4 | J2: 5290 | K2: Авито Доставка | M2: Заказать у поставщика до отсечки | N2: 28.09 | O2: образец заполнения — строку можно удалить | Q2: Всего обращений | R2: =COUNTA(H3:H302) -> 0
A3: 1 | Q3: 1. Новый | R3: =COUNTIF(H3:H302,"1. Новый") -> 0
A4: 2 | Q4: 2. Ждём VIN | R4: =COUNTIF(H3:H302,"2. Ждём VIN") -> 0
A5: 3 | Q5: 3. Подбор | R5: =COUNTIF(H3:H302,"3. Подбор") -> 0
A6: 4 | Q6: 4. Предложение | R6: =COUNTIF(H3:H302,"4. Предложение") -> 0
A7: 5 | Q7: 5. Думает | R7: =COUNTIF(H3:H302,"5. Думает") -> 0
A8: 6 | Q8: 6. Ждём оплату | R8: =COUNTIF(H3:H302,"6. Ждём оплату") -> 0
A9: 7 | Q9: 7. В обработке | R9: =COUNTIF(H3:H302,"7. В обработке") -> 0
A10: 8 | Q10: Отказ | R10: =COUNTIF(H3:H302,"Отказ") -> 0
A11: 9 | Q11: Доля заказов (в обработке ÷ всего) | R11: =IF(R2=0,"",COUNTIF(H3:H302,"7. В обработке")/R2)
A12: 10 | Q12: Среднее время первого ответа, мин | R12: =IFERROR(AVERAGE(I3:I302),"")
A13: 11 | Q13: Выручка по заказам в обработке, ₽ | R13: =SUMIF(H3:H302,"7. В обработке",J3:J302) -> 0
A14: 12
A15: 13 | Q15: Причины отказов
A16: 14 | Q16: не ответил | R16: =COUNTIF(L3:L302,"не ответил") -> 0
A17: 15 | Q17: дорого | R17: =COUNTIF(L3:L302,"дорого") -> 0
A18: 16 | Q18: не подошло | R18: =COUNTIF(L3:L302,"не подошло") -> 0
A19: 17 | Q19: нет в наличии | R19: =COUNTIF(L3:L302,"нет в наличии") -> 0
A20: 18 | Q20: долго ждать | R20: =COUNTIF(L3:L302,"долго ждать") -> 0
A21: 19 | Q21: купил в другом месте | R21: =COUNTIF(L3:L302,"купил в другом месте") -> 0
A22: 20 | Q22: мы отказали | R22: =COUNTIF(L3:L302,"мы отказали") -> 0
A23: 21 | Q23: другое | R23: =COUNTIF(L3:L302,"другое") -> 0
A24: 22 | Q24: Чаще всего | R24: =IF(SUM(R16:R23)=0,"",INDEX(Q16:Q23,MATCH(MAX(R16:R23),R16:R23,0)))
A25: 23
A26: 24
A27: 25
A28: 26
A29: 27
A30: 28
A31: 29
A32: 30
A33: 31
A34: 32
A35: 33
A36: 34
... A302: 300

Sheet Прогноз
A1: Прогноз на месяц (до налога): ТО, ГРМ и тормоз-киты
B3: ТО-кит | C3: ГРМ-кит | D3: Тормоз-кит | E3: Пояснение
A4: Средний чек кита, ₽ | B4: 4740 | C4: 10490 | D4: 5290 | E4: Среднее по собранным китам, уже с повышением цен: ТО-кит: Kia Picanto 1.0 / 1.2 (4 390 ₽), VW Jetta (5 090 ₽); ГРМ-кит: Geely Coolray 1.5T (10 490 ₽); Тормоз-кит: Kia Rio 2017–2021 (5 290 ₽), Hyundai Solaris 2017–2022 (5 290 ₽). Замените, когда соберёте больше китов.
A5: Средняя стоимость деталей, ₽ | B5: 3365.09 | C5: 7056.23 | D5: 3624.6 | E5: Среднее по деталям тех же китов (без упаковки).
A6: Доля оплат через Авито Доставку | B6: 0.5 | E6: Общая для всех китов. Остальные — прямым переводом. Ваша оценка; уточните по факту.
A7: Справка: средний чек по листу «Киты» | B7: =IFERROR(AVERAGEIFS(Киты!$M:$M,Киты!$B:$B,"ТО",Киты!$M:$M,">0"),"") | C7: =IFERROR(AVERAGEIFS(Киты!$M:$M,Киты!$B:$B,"ГРМ",Киты!$M:$M,">0"),"") | D7: =IFERROR(AVERAGEIFS(Киты!$M:$M,Киты!$B:$B,"Тормоза",Киты!$M:$M,">0"),"")
A8: Справка: средние детали по листу «Киты» | B8: =IFERROR(AVERAGEIFS(Киты!$I:$I,Киты!$B:$B,"ТО",Киты!$I:$I,">0"),"") | C8: =IFERROR(AVERAGEIFS(Киты!$I:$I,Киты!$B:$B,"ГРМ",Киты!$I:$I,">0"),"") | D8: =IFERROR(AVERAGEIFS(Киты!$I:$I,Киты!$B:$B,"Тормоза",Киты!$I:$I,">0"),"")
A9: Постоянные расходы в месяц, ₽ | B9: =(Параметры!$B$13+Параметры!$B$14+Параметры!$B$15+Параметры!$B$16+Параметры!$B$17) -> 12783 | E9: Сумма постоянных расходов с листа «Параметры». Платятся один раз в месяц на весь магазин.
A10: Прибыль с 1 заказа до постоянных расходов, ₽ | B10: =IF(B4="","",B4-(B5+Параметры!$B$3)-$B$6*B4*Параметры!$B$7-(1-$B$6)*(B4*Параметры!$B$11+Параметры!$B$12)-Параметры!$B$8-B5*Параметры!$B$9) -> 806.0155 | C10: =IF(C4="","",C4-(C5+Параметры!$B$3)-$B$6*C4*Параметры!$B$7-(1-$B$6)*(C4*Параметры!$B$11+Параметры!$B$12)-Параметры!$B$8-C5*Параметры!$B$9) -> 2473.3185 | D10: =IF(D4="","",D4-(D5+Параметры!$B$3)-$B$6*D4*Параметры!$B$7-(1-$B$6)*(D4*Параметры!$B$11+Параметры!$B$12)-Параметры!$B$8-D5*Параметры!$B$9) -> 1063.73
A11: Точка безубыточности, заказов в месяц | B11: =IF(B10="","",IF(B10<=0,"не окупается",ROUNDUP($B$9/B10,0))) -> 16 | C11: =IF(C10="","",IF(C10<=0,"не окупается",ROUNDUP($B$9/C10,0))) -> 6 | D11: =IF(D10="","",IF(D10<=0,"не окупается",ROUNDUP($B$9/D10,0))) -> 13 | E11: Сколько китов одного вида нужно продать, чтобы покрыть постоянные расходы.
A13: Сценарий | B13: ТО-китов | C13: ГРМ-китов | D13: Тормоз-китов | E13: Выручка, ₽ | F13: Детали и упаковка, ₽ | G13: Комиссия Авито, ₽ | H13: Комиссия банка, ₽ | I13: Показы, ₽ | J13: Резерв на товар, ₽ | K13: СДЭК за ваш счёт, ₽ | L13: Постоянные, ₽ | M13: Прибыль до налога, ₽ | N13: Прибыль на 1 заказ, ₽
A14: Только ТО | B14: 20 | C14: 0 | D14: 0 | E14: =N(B14)*N($B$4)+N(C14)*N($C$4)+N(D14)*N($D$4) -> 94800 | F14: =N(B14)*(N($B$5)+Параметры!$B$3)+N(C14)*(N($C$5)+Параметры!$B$3)+N(D14)*(N($D$5)+Параметры!$B$3) -> 68301.8 | G14: =$B$6*E14*Параметры!$B$7 -> 3081 | H14: =(1-$B$6)*E14*Параметры!$B$11 -> 331.8 | I14: =(B14+C14+D14)*Параметры!$B$8 -> 3600 | J14: =(N(B14)*N($B$5)+N(C14)*N($C$5)+N(D14)*N($D$5))*Параметры!$B$9 -> 3365.09 | K14: =(B14+C14+D14)*(1-$B$6)*Параметры!$B$12 -> 0 | L14: =$B$9 -> 12783 | M14: =E14-SUM(F14:L14) -> 3337.31 | N14: =IF((B14+C14+D14)=0,"",M14/(B14+C14+D14)) -> 166.8655
A15: Только ГРМ | B15: 0 | C15: 10 | D15: 0 | E15: =N(B15)*N($B$4)+N(C15)*N($C$4)+N(D15)*N($D$4) -> 104900 | F15: =N(B15)*(N($B$5)+Параметры!$B$3)+N(C15)*(N($C$5)+Параметры!$B$3)+N(D15)*(N($D$5)+Параметры!$B$3) -> 71062.3 | G15: =$B$6*E15*Параметры!$B$7 -> 3409.25 | H15: =(1-$B$6)*E15*Параметры!$B$11 -> 367.15 | I15: =(B15+C15+D15)*Параметры!$B$8 -> 1800 | J15: =(N(B15)*N($B$5)+N(C15)*N($C$5)+N(D15)*N($D$5))*Параметры!$B$9 -> 3528.115 | K15: =(B15+C15+D15)*(1-$B$6)*Параметры!$B$12 -> 0 | L15: =$B$9 -> 12783 | M15: =E15-SUM(F15:L15) -> 11950.185 | N15: =IF((B15+C15+D15)=0,"",M15/(B15+C15+D15)) -> 1195.0185
A16: Только тормоза | B16: 0 | C16: 0 | D16: 10 | E16: =N(B16)*N($B$4)+N(C16)*N($C$4)+N(D16)*N($D$4) -> 52900 | F16: =N(B16)*(N($B$5)+Параметры!$B$3)+N(C16)*(N($C$5)+Параметры!$B$3)+N(D16)*(N($D$5)+Параметры!$B$3) -> 36746 | G16: =$B$6*E16*Параметры!$B$7 -> 1719.25 | H16: =(1-$B$6)*E16*Параметры!$B$11 -> 185.15 | I16: =(B16+C16+D16)*Параметры!$B$8 -> 1800 | J16: =(N(B16)*N($B$5)+N(C16)*N($C$5)+N(D16)*N($D$5))*Параметры!$B$9 -> 1812.3 | K16: =(B16+C16+D16)*(1-$B$6)*Параметры!$B$12 -> 0 | L16: =$B$9 -> 12783 | M16: =E16-SUM(F16:L16) -> -2145.7 | N16: =IF((B16+C16+D16)=0,"",M16/(B16+C16+D16)) -> -214.57
A17: Старт | B17: 10 | C17: 5 | D17: 5 | E17: =N(B17)*N($B$4)+N(C17)*N($C$4)+N(D17)*N($D$4) -> 126300 | F17: =N(B17)*(N($B$5)+Параметры!$B$3)+N(C17)*(N($C$5)+Параметры!$B$3)+N(D17)*(N($D$5)+Параметры!$B$3) -> 88055.05 | G17: =$B$6*E17*Параметры!$B$7 -> 4104.75 | H17: =(1-$B$6)*E17*Параметры!$B$11 -> 442.05 | I17: =(B17+C17+D17)*Параметры!$B$8 -> 3600 | J17: =(N(B17)*N($B$5)+N(C17)*N($C$5)+N(D17)*N($D$5))*Параметры!$B$9 -> 4352.7525 | K17: =(B17+C17+D17)*(1-$B$6)*Параметры!$B$12 -> 0 | L17: =$B$9 -> 12783 | M17: =E17-SUM(F17:L17) -> 12962.397 | N17: =IF((B17+C17+D17)=0,"",M17/(B17+C17+D17)) -> 648.11987
A18: Рабочий месяц | B18: 20 | C18: 10 | D18: 10 | E18: =N(B18)*N($B$4)+N(C18)*N($C$4)+N(D18)*N($D$4) -> 252600 | F18: =N(B18)*(N($B$5)+Параметры!$B$3)+N(C18)*(N($C$5)+Параметры!$B$3)+N(D18)*(N($D$5)+Параметры!$B$3) -> 176110.1 | G18: =$B$6*E18*Параметры!$B$7 -> 8209.5 | H18: =(1-$B$6)*E18*Параметры!$B$11 -> 884.1 | I18: =(B18+C18+D18)*Параметры!$B$8 -> 7200 | J18: =(N(B18)*N($B$5)+N(C18)*N($C$5)+N(D18)*N($D$5))*Параметры!$B$9 -> 8705.505 | K18: =(B18+C18+D18)*(1-$B$6)*Параметры!$B$12 -> 0 | L18: =$B$9 -> 12783 | M18: =E18-SUM(F18:L18) -> 38707.795 | N18: =IF((B18+C18+D18)=0,"",M18/(B18+C18+D18)) -> 967.69488
A19: Хороший месяц | B19: 30 | C19: 15 | D19: 15 | E19: =N(B19)*N($B$4)+N(C19)*N($C$4)+N(D19)*N($D$4) -> 378900 | F19: =N(B19)*(N($B$5)+Параметры!$B$3)+N(C19)*(N($C$5)+Параметры!$B$3)+N(D19)*(N($D$5)+Параметры!$B$3) -> 264165.15 | G19: =$B$6*E19*Параметры!$B$7 -> 12314.25 | H19: =(1-$B$6)*E19*Параметры!$B$11 -> 1326.15 | I19: =(B19+C19+D19)*Параметры!$B$8 -> 10800 | J19: =(N(B19)*N($B$5)+N(C19)*N($C$5)+N(D19)*N($D$5))*Параметры!$B$9 -> 13058.257 | K19: =(B19+C19+D19)*(1-$B$6)*Параметры!$B$12 -> 0 | L19: =$B$9 -> 12783 | M19: =E19-SUM(F19:L19) -> 64453.192 | N19: =IF((B19+C19+D19)=0,"",M19/(B19+C19+D19)) -> 1074.2199
A20: Цель | B20: 50 | C20: 20 | D20: 20 | E20: =N(B20)*N($B$4)+N(C20)*N($C$4)+N(D20)*N($D$4) -> 552600 | F20: =N(B20)*(N($B$5)+Параметры!$B$3)+N(C20)*(N($C$5)+Параметры!$B$3)+N(D20)*(N($D$5)+Параметры!$B$3) -> 386371.1 | G20: =$B$6*E20*Параметры!$B$7 -> 17959.5 | H20: =(1-$B$6)*E20*Параметры!$B$11 -> 1934.1 | I20: =(B20+C20+D20)*Параметры!$B$8 -> 16200 | J20: =(N(B20)*N($B$5)+N(C20)*N($C$5)+N(D20)*N($D$5))*Параметры!$B$9 -> 19093.555 | K20: =(B20+C20+D20)*(1-$B$6)*Параметры!$B$12 -> 0 | L20: =$B$9 -> 12783 | M20: =E20-SUM(F20:L20) -> 98258.745 | N20: =IF((B20+C20+D20)=0,"",M20/(B20+C20+D20)) -> 1091.7638
A22: Налог не учтён. Число китов в колонках B–D можно менять. Подписка Авито уже входит в постоянные расходы.

Sheet Параметры
A1: Параметр | B1: Значение | C1: Пояснение / источник
A2: Наценка к закупке | B2: 0.3 | C2: Цена кита = (детали + упаковка) × (1 + наценка), вверх до шага округления, минус «вычесть». Ваше решение.
A3: Упаковка на 1 кит, ₽ | B3: 50 | C3: Коробка, наклейка, печать карты ремонта — оценка; уточните по факту.
A4: Шаг округления цены, ₽ | B4: 100 | C4: Цена округляется вверх до этого шага.
A5: Вычесть из округлённой цены, ₽ | B5: 10 | C5: Чтобы цена заканчивалась на …90 (4 700 → 4 690).
A6: Повышение цен ко всем китам | B6: 0.05 | C6: Ваше решение: +5% сверху ко всем китам — и к цене по наценке, и к цене по рынку (колонка Y на листе «Киты»). Затем снова округление до …90. Поставьте 0%, чтобы убрать.
A7: Комиссия Авито Доставки | B7: 0.065 | C7: Только для заказов через Авито Доставку. ≈6,5% по данным селлерских сервисов (SelSup, 2026) — сверьте в кабинете Авито.
A8: Показы объявления на 1 заказ, ₽ | B8: 180 | C8: Оценка: ≈150 показов × 1,2 ₽. Клиент пришёл с Авито при любой оплате, поэтому вычитается всегда. После запуска: расход на показы за месяц ÷ число заказов.
A9: Резерв на товар (возвраты, брак, довоз), % от деталей | B9: 0.05 | C9: Ваше решение: 5% от стоимости деталей. Через 2–3 месяца сверьте с фактом и поправьте.
A10: Резерв включать в цену? (1 — да, 0 — нет) | B10: 0 | C10: 0 — резерв вычитается из прибыли, цена не меняется. 1 — резерв добавляется к закупке, и цена кита растёт.
A11: Комиссия банка при оплате переводом | B11: 0.007 | C11: Для прямых переводов. Оплата по QR/СБП для бизнеса обычно 0,4–0,7%; обычный перевод на счёт ИП часто бесплатный — уточните у банка.
A12: СДЭК за ваш счёт при оплате переводом, ₽ | B12: 0 | C12: 0, если доставку оплачивает покупатель. Если отправляете бесплатно — впишите среднюю стоимость отправки.
A13: Взносы ИП, ₽ в месяц | B13: 4783 | C13: 57 390 ₽ за 2026 год ÷ 12 (фиксированные взносы ИП).
... A18: План заказов в месяц | B18: 20 | C18: На сколько заказов делятся постоянные расходы. Больше заказов — меньше расходов на один кит.
A19: Постоянные расходы на 1 кит, ₽ | B19: =($B$13+$B$14+$B$15+$B$16+$B$17)/MAX(1,$B$18) -> 639.15 | C19: Считается сам: сумма постоянных расходов в месяц ÷ план заказов.
A21: Налог в расчёт не входит: прибыль на листе «Киты» — до налога.

Sheet Состав
A1: Кит | B1: Машина | C1: Позиция | D1: Кол-во | E1: Бренд | F1: Артикул | G1: Фаворит | H1: Микадо | I1: Профит Лига | J1: Росско | K1: Автосоюз | L1: Автоспутник | M1: Автоформула | N1: Армтек | O1: Автотрейд | P1: Лучшая цена, ₽ | Q1: У кого | R1: Сумма, ₽ | S1: Комментарий
A2: ПРИМЕР | B2: образец заполнения — строку можно удалить | C2: Фильтр масляный | D2: 1 | E2: Бренд А | F2: ABC-123 | G2: 460 | I2: 445 | J2: 430 | N2: 470 | P2: =IF(COUNT(G2:O2)=0,"",MIN(G2:O2)) -> 430 | Q2: =IF(P2="","",INDEX($G$1:$O$1,MATCH(P2,G2:O2,0))) -> Росско | R2: =IF(P2="",0,P2*D2) -> 430 | S2: Цены — у тех поставщиков, где позиция есть; пустые ячейки не учитываются
A3: TO-01 | B3: =IFERROR(INDEX(Киты!$C:$C,MATCH(A3,Киты!$A:$A,0)),"") -> Hyundai Solaris 2010–2017 | C3: Масло моторное 4 л | D3: 1 | P3: =IF(COUNT(G3:O3)=0,"",MIN(G3:O3)) | Q3: =IF(P3="","",INDEX($G$1:$O$1,MATCH(P3,G3:O3,0))) | R3: =IF(P3="",0,P3*D3) -> 0 | S3: Вязкость и допуск — по мануалу автомобиля
A4: TO-01 | B4: =IFERROR(INDEX(Киты!$C:$C,MATCH(A4,Киты!$A:$A,0)),"") -> Hyundai Solaris 2010–2017 | C4: Фильтр масляный | D4: 1 | P4: =IF(COUNT(G4:O4)=0,"",MIN(G4:O4)) | Q4: =IF(P4="","",INDEX($G$1:$O$1,MATCH(P4,G4:O4,0))) | R4: =IF(P4="",0,P4*D4) -> 0
A5: TO-01 | B5: =IFERROR(INDEX(Киты!$C:$C,MATCH(A5,Киты!$A:$A,0)),"") -> Hyundai Solaris 2010–2017 | C5: Фильтр воздушный | D5: 1 | P5: =IF(COUNT(G5:O5)=0,"",MIN(G5:O5)) | Q5: =IF(P5="","",INDEX($G$1:$O$1,MATCH(P5,G5:O5,0))) | R5: =IF(P5="",0,P5*D5) -> 0
A6: TO-01 | B6: =IFERROR(INDEX(Киты!$C:$C,MATCH(A6,Киты!$A:$A,0)),"") -> Hyundai Solaris 2010–2017 | C6: Фильтр салонный | D6: 1 | P6: =IF(COUNT(G6:O6)=0,"",MIN(G6:O6)) | Q6: =IF(P6="","",INDEX($G$1:$O$1,MATCH(P6,G6:O6,0))) | R6: =IF(P6="",0,P6*D6) -> 0
A7: TO-01 | B7: =IFERROR(INDEX(Киты!$C:$C,MATCH(A7,Киты!$A:$A,0)),"") -> Hyundai Solaris 2010–2017 | C7: Шайба (прокладка) сливной пробки | D7: 1 | P7: =IF(COUNT(G7:O7)=0,"",MIN(G7:O7)) | Q7: =IF(P7="","",INDEX($G$1:$O$1,MATCH(P7,G7:O7,0))) | R7: =IF(P7="",0,P7*D7) -> 0
A8: TO-02 | B8: =IFERROR(INDEX(Киты!$C:$C,MATCH(A8,Киты!$A:$A,0)),"") -> Hyundai Solaris 2017–2022 | C8: Масло моторное 4 л | D8: 1 | P8: =IF(COUNT(G8:O8)=0,"",MIN(G8:O8)) | Q8: =IF(P8="","",INDEX($G$1:$O$1,MATCH(P8,G8:O8,0))) | R8: =IF(P8="",0,P8*D8) -> 0 | S8: Вязкость и допуск — по мануалу автомобиля
A9: TO-02 | B9: =IFERROR(INDEX(Киты!$C:$C,MATCH(A9,Киты!$A:$A,0)),"") -> Hyundai Solaris 2017–2022 | C9: Фильтр масляный | D9: 1 | P9: =IF(COUNT(G9:O9)=0,"",MIN(G9:O9)) | Q9: =IF(P9="","",INDEX($G$1:$O$1,MATCH(P9,G9:O9,0))) | R9: =IF(P9="",0,P9*D9) -> 0
A10: TO-02 | B10: =IFERROR(INDEX(Киты!$C:$C,MATCH(A10,Киты!$A:$A,0)),"") -> Hyundai Solaris 2017–2022 | C10: Фильтр воздушный | D10: 1 | P10: =IF(COUNT(G10:O10)=0,"",MIN(G10:O10)) | Q10: =IF(P10="","",INDEX($G$1:$O$1,MATCH(P10,G10:O10,0))) | R10: =IF(P10="",0,P10*D10) -> 0
A11: TO-02 | B11: =IFERROR(INDEX(Киты!$C:$C,MATCH(A11,Киты!$A:$A,0)),"") -> Hyundai Solaris 2017–2022 | C11: Фильтр салонный | D11: 1 | P11: =IF(COUNT(G11:O11)=0,"",MIN(G11:O11)) | Q11: =IF(P11="","",INDEX($G$1:$O$1,MATCH(P11,G11:O11,0))) | R11: =IF(P11="",0,P11*D11) -> 0
A12: TO-02 | B12: =IFERROR(INDEX(Киты!$C:$C,MATCH(A12,Киты!$A:$A,0)),"") -> Hyundai Solaris 2017–2022 | C12: Шайба (прокладка) сливной пробки | D12: 1 | P12: =IF(COUNT(G12:O12)=0,"",MIN(G12:O12)) | Q12: =IF(P12="","",INDEX($G$1:$O$1,MATCH(P12,G12:O12,0))) | R12: =IF(P12="",0,P12*D12) -> 0
A13: TO-03 | B13: =IFERROR(INDEX(Киты!$C:$C,MATCH(A13,Киты!$A:$A,0)),"") -> Kia Rio 2011–2017 | C13: Масло моторное 4 л | D13: 1 | P13: =IF(COUNT(G13:O13)=0,"",MIN(G13:O13)) | Q13: =IF(P13="","",INDEX($G$1:$O$1,MATCH(P13,G13:O13,0))) | R13: =IF(P13="",0,P13*D13) -> 0 | S13: Вязкость и допуск — по мануалу автомобиля
A14: TO-03 | B14: =IFERROR(INDEX(Киты!$C:$C,MATCH(A14,Киты!$A:$A,0)),"") -> Kia Rio 2011–2017 | C14: Фильтр масляный | D14: 1 | P14: =IF(COUNT(G14:O14)=0,"",MIN(G14:O14)) | Q14: =IF(P14="","",INDEX($G$1:$O$1,MATCH(P14,G14:O14,0))) | R14: =IF(P14="",0,P14*D14) -> 0
A15: TO-03 | B15: =IFERROR(INDEX(Киты!$C:$C,MATCH(A15,Киты!$A:$A,0)),"") -> Kia Rio 2011–2017 | C15: Фильтр воздушный | D15: 1 | P15: =IF(COUNT(G15:O15)=0,"",MIN(G15:O15)) | Q15: =IF(P15="","",INDEX($G$1:$O$1,MATCH(P15,G15:O15,0))) | R15: =IF(P15="",0,P15*D15) -> 0
A16: TO-03 | B16: =IFERROR(INDEX(Киты!$C:$C,MATCH(A16,Киты!$A:$A,0)),"") -> Kia Rio 2011–2017 | C16: Фильтр салонный | D16: 1 | P16: =IF(COUNT(G16:O16)=0,"",MIN(G16:O16)) | Q16: =IF(P16="","",INDEX($G$1:$O$1,MATCH(P16,G16:O16,0))) | R16: =IF(P16="",0,P16*D16) -> 0
A17: TO-03 | B17: =IFERROR(INDEX(Киты!$C:$C,MATCH(A17,Киты!$A:$A,0)),"") -> Kia Rio 2011–2017 | C17: Шайба (прокладка) сливной пробки | D17: 1 | P17: =IF(COUNT(G17:O17)=0,"",MIN(G17:O17)) | Q17: =IF(P17="","",INDEX($G$1:$O$1,MATCH(P17,G17:O17,0))) | R17: =IF(P17="",0,P17*D17) -> 0
A18: TO-04 | B18: =IFERROR(INDEX(Киты!$C:$C,MATCH(A18,Киты!$A:$A,0)),"") -> Kia Rio 2017–2021 | C18: Масло моторное 4 л | D18: 1 | P18: =IF(COUNT(G18:O18)=0,"",MIN(G18:O18)) | Q18: =IF(P18="","",INDEX($G$1:$O$1,MATCH(P18,G18:O18,0))) | R18: =IF(P18="",0,P18*D18) -> 0 | S18: Вязкость и допуск — по мануалу автомобиля
A19: TO-04 | B19: =IFERROR(INDEX(Киты!$C:$C,MATCH(A19,Киты!$A:$A,0)),"") -> Kia Rio 2017–2021 | C19: Фильтр масляный | D19: 1 | P19: =IF(COUNT(G19:O19)=0,"",MIN(G19:O19)) | Q19: =IF(P19="","",INDEX($G$1:$O$1,MATCH(P19,G19:O19,0))) | R19: =IF(P19="",0,P19*D19) -> 0
A20: TO-04 | B20: =IFERROR(INDEX(Киты!$C:$C,MATCH(A20,Киты!$A:$A,0)),"") -> Kia Rio 2017–2021 | C20: Фильтр воздушный | D20: 1 | P20: =IF(COUNT(G20:O20)=0,"",MIN(G20:O20)) | Q20: =IF(P20="","",INDEX($G$1:$O$1,MATCH(P20,G20:O20,0))) | R20: =IF(P20="",0,P20*D20) -> 0
A21: TO-04 | B21: =IFERROR(INDEX(Киты!$C:$C,MATCH(A21,Киты!$A:$A,0)),"") -> Kia Rio 2017–2021 | C21: Фильтр салонный | D21: 1 | P21: =IF(COUNT(G21:O21)=0,"",MIN(G21:O21)) | Q21: =IF(P21="","",INDEX($G$1:$O$1,MATCH(P21,G21:O21,0))) | R21: =IF(P21="",0,P21*D21) -> 0
A22: TO-04 | B22: =IFERROR(INDEX(Киты!$C:$C,MATCH(A22,Киты!$A:$A,0)),"") -> Kia Rio 2017–2021 | C22: Шайба (прокладка) сливной пробки | D22: 1 | P22: =IF(COUNT(G22:O22)=0,"",MIN(G22:O22)) | Q22: =IF(P22="","",INDEX($G$1:$O$1,MATCH(P22,G22:O22,0))) | R22: =IF(P22="",0,P22*D22) -> 0
A23: TO-05 | B23: =IFERROR(INDEX(Киты!$C:$C,MATCH(A23,Киты!$A:$A,0)),"") -> VW Polo 1.6 CFNA | C23: Масло моторное 4 л | D23: 1 | P23: =IF(COUNT(G23:O23)=0,"",MIN(G23:O23)) | Q23: =IF(P23="","",INDEX($G$1:$O$1,MATCH(P23,G23:O23,0))) | R23: =IF(P23="",0,P23*D23) -> 0 | S23: Вязкость и допуск — по мануалу автомобиля
A24: TO-05 | B24: =IFERROR(INDEX(Киты!$C:$C,MATCH(A24,Киты!$A:$A,0)),"") -> VW Polo 1.6 CFNA | C24: Фильтр масляный | D24: 1 | P24: =IF(COUNT(G24:O24)=0,"",MIN(G24:O24)) | Q24: =IF(P24="","",INDEX($G$1:$O$1,MATCH(P24,G24:O24,0))) | R24: =IF(P24="",0,P24*D24) -> 0
A25: TO-05 | B25: =IFERROR(INDEX(Киты!$C:$C,MATCH(A25,Киты!$A:$A,0)),"") -> VW Polo 1.6 CFNA | C25: Фильтр воздушный | D25: 1 | P25: =IF(COUNT(G25:O25)=0,"",MIN(G25:O25)) | Q25: =IF(P25="","",INDEX($G$1:$O$1,MATCH(P25,G25:O25,0))) | R25: =IF(P25="",0,P25*D25) -> 0
A26: TO-05 | B26: =IFERROR(INDEX(Киты!$C:$C,MATCH(A26,Киты!$A:$A,0)),"") -> VW Polo 1.6 CFNA | C26: Фильтр салонный | D26: 1 | P26: =IF(COUNT(G26:O26)=0,"",MIN(G26:O26)) | Q26: =IF(P26="","",INDEX($G$1:$O$1,MATCH(P26,G26:O26,0))) | R26: =IF(P26="",0,P26*D26) -> 0
A27: TO-05 | B27: =IFERROR(INDEX(Киты!$C:$C,MATCH(A27,Киты!$A:$A,0)),"") -> VW Polo 1.6 CFNA | C27: Шайба (прокладка) сливной пробки | D27: 1 | P27: =IF(COUNT(G27:O27)=0,"",MIN(G27:O27)) | Q27: =IF(P27="","",INDEX($G$1:$O$1,MATCH(P27,G27:O27,0))) | R27: =IF(P27="",0,P27*D27) -> 0
A28: TO-06 | B28: =IFERROR(INDEX(Киты!$C:$C,MATCH(A28,Киты!$A:$A,0)),"") -> VW Polo 1.6 CWVA | C28: Масло моторное 4 л | D28: 1 | P28: =IF(COUNT(G28:O28)=0,"",MIN(G28:O28)) | Q28: =IF(P28="","",INDEX($G$1:$O$1,MATCH(P28,G28:O28,0))) | R28: =IF(P28="",0,P28*D28) -> 0 | S28: Вязкость и допуск — по мануалу автомобиля
A29: TO-06 | B29: =IFERROR(INDEX(Киты!$C:$C,MATCH(A29,Киты!$A:$A,0)),"") -> VW Polo 1.6 CWVA | C29: Фильтр масляный | D29: 1 | P29: =IF(COUNT(G29:O29)=0,"",MIN(G29:O29)) | Q29: =IF(P29="","",INDEX($G$1:$O$1,MATCH(P29,G29:O29,0))) | R29: =IF(P29="",0,P29*D29) -> 0
A30: TO-06 | B30: =IFERROR(INDEX(Киты!$C:$C,MATCH(A30,Киты!$A:$A,0)),"") -> VW Polo 1.6 CWVA | C30: Фильтр воздушный | D30: 1 | P30: =IF(COUNT(G30:O30)=0,"",MIN(G30:O30)) | Q30: =IF(P30="","",INDEX($G$1:$O$1,MATCH(P30,G30:O30,0))) | R30: =IF(P30="",0,P30*D30) -> 0
A31: TO-06 | B31: =IFERROR(INDEX(Киты!$C:$C,MATCH(A31,Киты!$A:$A,0)),"") -> VW Polo 1.6 CWVA | C31: Фильтр салонный | D31: 1 | P31: =IF(COUNT(G31:O31)=0,"",MIN(G31:O31)) | Q31: =IF(P31="","",INDEX($G$1:$O$1,MATCH(P31,G31:O31,0))) | R31: =IF(P31="",0,P31*D31) -> 0
A32: TO-06 | B32: =IFERROR(INDEX(Киты!$C:$C,MATCH(A32,Киты!$A:$A,0)),"") -> VW Polo 1.6 CWVA | C32: Шайба (прокладка) сливной пробки | D32: 1 | P32: =IF(COUNT(G32:O32)=0,"",MIN(G32:O32)) | Q32: =IF(P32="","",INDEX($G$1:$O$1,MATCH(P32,G32:O32,0))) | R32: =IF(P32="",0,P32*D32) -> 0
A33: TO-07 | B33: =IFERROR(INDEX(Киты!$C:$C,MATCH(A33,Киты!$A:$A,0)),"") -> Haval Jolion 1.5T | C33: Масло моторное 4 л | D33: 1 | P33: =IF(COUNT(G33:O33)=0,"",MIN(G33:O33)) | Q33: =IF(P33="","",INDEX($G$1:$O$1,MATCH(P33,G33:O33,0))) | R33: =IF(P33="",0,P33*D33) -> 0 | S33: Вязкость и допуск — по мануалу автомобиля
A34: TO-07 | B34: =IFERROR(INDEX(Киты!$C:$C,MATCH(A34,Киты!$A:$A,0)),"") -> Haval Jolion 1.5T | C34: Масло моторное 1 л (если объём > 4 л) | D34: 0 | P34: =IF(COUNT(G34:O34)=0,"",MIN(G34:O34)) | Q34: =IF(P34="","",INDEX($G$1:$O$1,MATCH(P34,G34:O34,0))) | R34: =IF(P34="",0,P34*D34) -> 0 | S34: Поставьте 1, если объём заливки с фильтром больше 4 л (проверьте по VIN)
A35: TO-07 | B35: =IFERROR(INDEX(Киты!$C:$C,MATCH(A35,Киты!$A:$A,0)),"") -> Haval Jolion 1.5T | C35: Фильтр масляный | D35: 1 | P35: =IF(COUNT(G35:O35)=0,"",MIN(G35:O35)) | Q35: =IF(P35="","",INDEX($G$1:$O$1,MATCH(P35,G35:O35,0))) | R35: =IF(P35="",0,P35*D35) -> 0
A36: TO-07 | B36: =IFERROR(INDEX(Киты!$C:$C,MATCH(A36,Киты!$A:$A,0)),"") -> Haval Jolion 1.5T | C36: Фильтр воздушный | D36: 1 | P36: =IF(COUNT(G36:O36)=0,"",MIN(G36:O36)) | Q36: =IF(P36="","",INDEX($G$1:$O$1,MATCH(P36,G36:O36,0))) | R36: =IF(P36="",0,P36*D36) -> 0
A37: TO-07 | B37: =IFERROR(INDEX(Киты!$C:$C,MATCH(A37,Киты!$A:$A,0)),"") -> Haval Jolion 1.5T | C37: Фильтр салонный | D37: 1 | P37: =IF(COUNT(G37:O37)=0,"",MIN(G37:O37)) | Q37: =IF(P37="","",INDEX($G$1:$O$1,MATCH(P37,G37:O37,0))) | R37: =IF(P37="",0,P37*D37) -> 0
A38: TO-07 | B38: =IFERROR(INDEX(Киты!$C:$C,MATCH(A38,Киты!$A:$A,0)),"") -> Haval Jolion 1.5T | C38: Шайба (прокладка) сливной пробки | D38: 1 | P38: =IF(COUNT(G38:O38)=0,"",MIN(G38:O38)) | Q38: =IF(P38="","",INDEX($G$1:$O$1,MATCH(P38,G38:O38,0))) | R38: =IF(P38="",0,P38*D38) -> 0
A39: TO-08 | B39: =IFERROR(INDEX(Киты!$C:$C,MATCH(A39,Киты!$A:$A,0)),"") -> Haval F7 / F7x 1.5T | C39: Масло моторное 4 л | D39: 1 | P39: =IF(COUNT(G39:O39)=0,"",MIN(G39:O39)) | Q39: =IF(P39="","",INDEX($G$1:$O$1,MATCH(P39,G39:O39,0))) | R39: =IF(P39="",0,P39*D39) -> 0 | S39: Вязкость и допуск — по мануалу автомобиля
A40: TO-08 | B40: =IFERROR(INDEX(Киты!$C:$C,MATCH(A40,Киты!$A:$A,0)),"") -> Haval F7 / F7x 1.5T | C40: Масло моторное 1 л (если объём > 4 л) | D40: 0 | P40: =IF(COUNT(G40:O40)=0,"",MIN(G40:O40)) | Q40: =IF(P40="","",INDEX($G$1:$O$1,MATCH(P40,G40:O40,0))) | R40: =IF(P40="",0,P40*D40) -> 0 | S40: Поставьте 1, если объём заливки с фильтром больше 4 л (проверьте по VIN)
...

Sheet Поставщики
A1: Поставщик | B1: Статус | C1: Склад / пункт выдачи в Сочи или Адлере | D1: Отсечка заказа (до …) | E1: Срок до вас, дней | F1: Доставка до вас | G1: Возврат «не подошло» (срок, удержание) | H1: Отсрочка платежа | I1: Прайс / API | J1: Менеджер (имя, телефон) | K1: Комментарий
A2: ПРИМЕР | B2: подключён | C2: да, Адлер | D2: 12:00 | E2: 1 | F2: бесплатно от 3 000 ₽ | G2: 14 дней, без удержания | H2: после 3 мес., 14 дней | I2: API | J2: Иван, +7 … | K2: образец заполнения — строку можно удалить
A3: Фаворит | B3: подключён
A4: Микадо | B4: подключён
A5: Профит Лига | B5: подключён
A6: Росско | B6: подключён
A7: Автосоюз | B7: подключён
A8: Автоспутник | B8: подключён
A9: Автоформула | B9: в процессе
A10: Армтек | B10: подключён
A11: Автотрейд | B11: подключён

Sheet Моторы
A1: Машина | B1: Годы | C1: Мотор | D1: Привод ГРМ | E1: Что берём в ГРМ-кит | F1: Масло (объём) | G1: Источник / уверенность
A2: Hyundai Solaris / Kia Rio | B2: 2010–2017 | C2: G4FA 1.4 / G4FC 1.6 (Gamma) | D2: цепь | E2: Комплект цепи (цепь, натяжитель, успокоители), сальник коленвала, герметик; помпа и маслонасос — если требуется | F2: ≈3,3 л — хватает канистры 4 л; проверьте по VIN | G2: Данные каталогов производителя. Проверяйте по VIN в каталоге поставщика.
A3: Hyundai Solaris / Kia Rio | B3: 2017–2022 | C3: G4LC 1.4 (Kappa) / G4FG 1.6 (Gamma II) | D3: цепь | E3: Комплект цепи (цепь, натяжитель, успокоители), сальник коленвала, герметик; помпа и маслонасос — если требуется | F3: до 4 л — проверьте по VIN | G3: Данные каталогов производителя. Проверяйте по VIN.
A4: VW Polo седан | B4: 2010–2015 | C4: CFNA / CFNB 1.6 | D4: цепь | E4: Комплект цепи (цепь, натяжитель, успокоители), сальник коленвала, герметик; помпа и маслонасос — если требуется | F4: ≈3,6 л — проверьте по VIN | G4: Данные каталогов производителя. Проверяйте по VIN.
A5: VW Polo седан / лифтбек | B5: 2015+ | C5: CWVA / CWVB 1.6 | D5: ремень | E5: Комплект ремня (ремень, натяжной ролик); помпа — по желанию | F5: ≈3,6 л — проверьте по VIN | G5: Данные каталогов производителя. Проверяйте по VIN.
A6: Haval Jolion | B6: 2021+ | C6: GW4B15A 1.5T | D6: цепь | E6: Комплект цепи (цепь, натяжитель, успокоители), сальник коленвала, герметик; помпа и маслонасос — если требуется | F6: уточните по VIN (может быть > 4 л) | G6: Цепь: drive2.ru/l/726006979138433863, bus-tech.ru (замена цепи Jolion 1.5T)
A7: Haval F7 / F7x | B7: 2019+ | C7: GW4B15 1.5T / GW4C20 2.0T | D7: цепь | E7: Комплект цепи (цепь, натяжитель, успокоители), сальник коленвала, герметик; помпа и маслонасос — если требуется | F7: уточните по VIN (может быть > 4 л) | G7: Цепь; у 1.5T внимания требует к 100–120 тыс. км, у 2.0T часто 150+ тыс. км: bus-tech.ru/haval1/remont-f7/zamena-tsepi-grm-f7-f7x
A8: Chery Tiggo 7 Pro / 4 Pro | B8: 2020+ | C8: SQRE4T15C 1.5T | D8: цепь | E8: Комплект цепи (цепь, натяжитель, успокоители), сальник коленвала, герметик; помпа и маслонасос — если требуется | F8: уточните по VIN (может быть > 4 л) | G8: Цепь; ресурс часто 200+ тыс. км, поэтому ГРМ-кит — «позже». Комплекты Gates под SQRE4T15C продаются на Яндекс Маркете
A9: Geely Coolray | B9: 2020+ | C9: JLH-3G15TD 1.5T | D9: ремень + ремень помпы | E9: Ремень ГРМ, натяжной ролик, ремень привода помпы (по регламенту меняют вместе); помпа — если требуется | F9: уточните по VIN (может быть > 4 л) | G9: Ремень; регламент 100–120 тыс. км или 5–6 лет, на практике ≈80 тыс.: motorhunter.ru/engine/geely/jlh-3g15td/, avtogermes.ru
